### 1、概述
+ 生成器是es6新增的一个极为灵活的结构，拥有在一个函数块内暂停和恢复代码执行的能力，使用生成器可以自定义迭代器和实现协程
### 2、生成器基础
+ 生成器的形式是一个函数，函数名前面添加一个( \* )表示它是一个生成器。只要是可以定义函数的地方就可以定义生成器
```js
	 //生成器函数声明
	function* generatorFn(){}
	//生成器函数表达式声明
	let generatorFn = function* (){}
	//作为对象字面量方法的生成器函数
	let foo = {
		*generatorFn(){}
	}
	//作为实例方法的生成器函数
	class Foo{
		*generatorFn(){}
	}
	//作为静态方法的生成器函数
	class Bar{
		static* generatorFn(){}
	}
```
+ 调用生成器函数会产生一个**生成器对象**。生成器对象一开始处于暂停执行的状态。与迭代器相似，生成器对象也实现了Iterator接口，因此具有next()方法。调用这个方法会让生成器开始或恢复执行
+ next( )方法类似于迭代器，有一个done属性和一个value属性。函数体为空的生成器函数中间不会停留，调用一次next( )就会让done:true状态
+ 生成器对象实现了Iterator接口，它们默认的迭代器是自引用的
```js
	function* generatorFn(){
		console.log("执行");
		return "foo";
	}
	let generatorObj = generatorFn();
	//初次调用生成器函数不会打印日志
	console.log(generatorObj.next());
	//执行，{value: 'foo', done: true}
	console.log(generatorObj[Symbol.iterator]());
	//generatorFn {<closed>}
	console.log(generatorObj === generatorObj[Symbol.iterator]());
	//true
```
### 3、通过yield中断执行
+ yield关键字可以让生成器停止和开始工作，生成器在遇到yield关键字之前会正常运行。遇到这个关键字之后，执行将会停l止，函数的作用域状态会保留，也就是说对于同一个生成器而言，遇到yield执行停止，下一次不会从头开始。执行停止的生成器函数只能通过在生成器对象上调用next方法来恢复执行
+ yield关键字后面的表达式的值返回给生成器的调用者
+ yield关键字实际返回一个IteratorResult（[迭代器]）对象，它有两个属性，value和done，分别代表返回值和是否完成
```js
	function* generatorFn(){
		yield "a";
		yield "b";
		yield "c";
		yield "d";
		return "foo";
	}
	let generatorObj = generatorFn();  
	console.log(generatorObj.next());
	//{value: 'a', done: false}
	console.log(generatorObj.next());
	//{value: 'b', done: false}
	console.log(generatorObj.next());
	//{value: 'c', done: false}
	console.log(generatorObj.next().value);
	//d
	console.log(generatorObj.next());
	//{value: 'foo', done: true}
```
+ next()方法每次执行都会进入生成器yield的下一个，再遇到return之前done属性都为false
+ 生成器函数内部的执行流程会针对每个生成器对象区分作用域。在一个生成器对象上调用next()不会影响其他生成器：
```js
	function* generatorFn(){
		yield "a";
		yield "b";
		yield "c";
		yield "d";
		return "foo";
	}
	let generatorObj1 = generatorFn();
	let generatorObj2 = generatorFn();
	console.log(generatorObj1.next());
	//{value: 'a', done: false}
	console.log(generatorObj2.next());
	//{value: 'a', done: false}
```
+ yield只能在生成器函数内部使用，其他地方会抛出错误
### 4、生成器对象作为可迭代对象
+ 生成器生成的生成器对象为可迭代对象
+ 在需要自定义迭代对象的时候，这样使用生成器对象会很有用。比如我们可以自定义迭代次数可以通过生成器来使用
```js
	let arr = [1,2,3,4,5,6];
	function* nTimes(n){
		while(n--){
			yield;
		}
	}
	let iteratorArr = arr.values();
	for(let _ of nTimes(3)){
	   console.log(iteratorArr.next().value);
	   //1 2 3
	}
```
### 5、使用yield实现输入与输出
+ 除了可以作为函数中间返回语句使用，yield关键字还可作为函数的中间参数使用。**上一次让生成器函数暂停的yield关键字会接收next()方法的第一个值。这里有个地方，第一次调用next()传入的值不会被使用，因为这一次调用是为了开始执行生成器函数**
```js
	function* generatorFn(initial){
		for(let i = 0 ; i < initial ; i++ ){
		   yield i;
		}
	}
	let generatorObj = generatorFn(4);
	for(let i = 2 ; i < 6 ; i++){
		console.log(generatorObj.next(i));
		//0 1 2 3
	}
```
---
```js
	function* generatorFn(initial){
	   console.log(initial);
	   console.log(yield);
	   console.log(yield);
	   console.log(yield);
	}
	let generatorObj = generatorFn(4);
	generatorObj.next(3);//4
	generatorObj.next("foo");//foo
	generatorObj.next("baz");//baz
	generatorObj.next("bar");//bar
```
+ 因为函数必须对整个表达式求值才能确定要返回的值，所有当它遇到yield关键字的时候暂停执行并计算要产生的值：“3”。下一次调用next( )传入了“foo”，作为交给同一个yield的值。然后这个值被确定为本次生成器函数要返回的值。
### 6、产生可迭代对象
+ 可使用\*增强yield的行为，让它能够迭代一个可迭代的对象，从而一次产出一个值：
```js
	function* generatorFn(){
		yield* [1,2,3,4];
	}
	let generatorObj = generatorFn();
	for(let x of generatorObj){
		console.log(x);//1 2 3 4
		//x接收value的值
	}
```
+ 因为yield\*实际上只是将一个可迭代对象序列化为一连串可以单独产出的值，所以着跟把yield放到一个循环里并没有什么不同，所以与遍历可迭代对象是一样的
```js
	function* generatorFn(){
		yield* [1,2,3,4];
	}
	//与：
	function* generatorFn(){
		for(let i of [1,2,3,4]){
			yield i;
		}
	}
```
+ `yield*` 表达式本身的值是当迭代器关闭时返回的值（即`done`为`true`时）。
```js
	function* generatorFn(){
		yield* [1,2,3,4];
		yield "bar";
	}
	function* getGenerator(){
		console.log("iter:",yield* generatorFn());
	}
	for(const node of getGenerator()){
		console.log("value:",node);
	}
	//value: 1
	//value: 2
	//value: 3
	//value: 4
	//iter: bar
```
+ 对于生成器产生的迭代器来说，这个值就是生成器函数返回的值，说人话就是每次生成器启动返回的值
### 7、使用yield\*实现递归算法
+ yield\*最有用的地方就是实现递归操作，此时生成器可以产生自身
```js
	function* nTimes(n){
		if(n>0){
			yield* nTimes(n-1);
			yield n - 1;
		}
	}
	for(const node of nTimes(5)){
		console.log(node);//0 1 2 3 4
	}
```
---
```js
    function* nTimes(n){
        if(n == 1){
            return 1;
        }
        if(n == 2){
            return 2;
        }
        if(n > 2){
            let a = yield* nTimes(n - 1);
            let b = yield* nTimes(n - 2);
            yield a + b;
            return a + b;
        }
    }
    for(const node of nTimes(5)){
        console.log(node);//3 5 3 8
    }
```
### 8、生成器作为默认迭代器
+ 因为生成器实现Iterable接口，而且生成器函数与默认迭代器被调用之后都产生了迭代器，所以生成器格外合适作为默认迭代器
```js
	class Fo{
		constructor(){
			this.name = "张三";
		}
		*[Symbol.iterator] () {
			yield* this.name;
		}
	}
	const f = new Fo();
	for(const i of f){
		console.log(i);//张  三
	}
```
### 9、提前终止生成器
+ 与迭代器类似，生成器也支持“可关闭”状态。一个iterator接口的对象一定由next()方法还有return()方法，除此之外，生成器还有第三个方法：throw()
#### 9.1、return()方法
+ 与迭代器不同，所有生成器对象都有return( )方法，通过它关闭生成器，那么done:true状态，提供的任何返回值都不会被存储或传播
```js
	function* generatorFn(){
		yield* [1,2,3,4,5];
	}
	let gen = generatorFn();
	let ner = generatorFn();
	console.log(gen.next());
	//{value: 1, done: false}
	console.log(gen.next());
	//{value: 2, done: false}
	console.log(gen.return(4));
	//{value: 4, done: true}
	console.log(gen.next());
	//{value: undefined, done: true}
	console.log(gen.next());
	//{value: undefined, done: true}
	for(const x of ner){
		if(x > 2){
			ner.return(6)
		}
		console.log(x);//1 2 3
	}
```
+ for-of循环等内置语言结构会忽略状态为done:true的IteratorObjet内部返回值
#### 9.2、throw()方法
+ throw()方法会在暂停的时候将一个提供错误注入到生成器对象中。如果错误未被处理，生成器便会被关闭
```js
	function* generatorFn(){
		for(const x of [1,2,3]){
			yield x;
		}
	}
	const g =generatorFn();
	console.log(g.next());
	//{value: 1, done: false}
	try{
		g.throw("foo");
	}catch(e){
		console.log(e);//foo
	}
	console.log(g.next());
	//{value: undefined, done: true}
```
+ 不过若生成器函数在内部解决了这个错误，那么生成器不会关闭，而且开可以恢复执行。错误处理会跳过对应的yield，因此在例子中会跳过一个值。比如：
```js
	function* generatorFn(){
	   for(const node of [1,2,3,4,5]){
		try{
			yield node;
		}catch(e){
			console.log("发生错误");
		}
	   }
	}
	const g =generatorFn();
	console.log(g.next());
	//{value: 1, done: false}
	g.throw("foo");//发生错误
	console.log(g.next());
	//{value: 3, done: false}
	console.log(g.next());
	//{value: 4, done: false}
```
+ 在这里生成器在try/catch中yield关键字暂停执行。在暂停期间，throw()方法向生成器对象内部注入了一个错误：字符串“foo”。这个错误被yield关键字抛出，被try/cathc捕获到错误，可是由于yiled抛出了错误所以不会再产生2，此时生成器函数继续执行，下一次抛出3
+ 若生成器对象还没开始执行就调用throw()抛出异常那么不会再函数内部被捕获因为这是再函数外抛出异常